Workbook
Name SegmentaciónDeDatos_EMPRESA: #N/A
Name SegmentaciónDeDatos_MES: #N/A
Name SegmentaciónDeDatos_SEMANA: #N/A

Sheet DasbhboardPrevencionista
A1: EMPRESA | B1: ACTIVIDAD | C1: FECHA PROGRAMADO | D1: ESTADO
A2: APLOMO | B2: Envío de índices de accidentabilidad enero y febrero 2026 | C2: 46087 | D2: HECHO
A3: APLOMO | B3: Inducción de Seguridad – Rubén Moreno | C3: 46072 | D3: HECHO
A4: APLOMO | B4: Inspección de seguridad | C4: 46100 | D4: HECHO
A5: APLOMO | B5: Inspección de seguridad | C5: 46114 | D5: PROGRAMADO
A6: APLOMO | B6: Inspección de seguridad | C6: 46128 | D6: PROGRAMADO
A7: APLOMO | B7: Inspección de seguridad | C7: 46142 | D7: PROGRAMADO
A8: APLOMO | B8: Inspección de seguridad | C8: 46172 | D8: PROGRAMADO
A9: APLOMO | B9: Inspección de seguridad | C9: 46202 | D9: PROGRAMADO
A10: APLOMO | B10: Inspección de seguridad | C10: 46232 | D10: PROGRAMADO
A11: APLOMO | B11: Inspección de seguridad | C11: 46262 | D11: PROGRAMADO
A12: APLOMO | B12: Inspección de seguridad | C12: 46292 | D12: PROGRAMADO
A13: APLOMO | B13: Inspección de seguridad | C13: 46322 | D13: PROGRAMADO
... A177: RABUFFER | B177: Reunión Bipartita | C177: 46141 | D177: PROGRAMADO

Sheet Planificación Anual
A1: PLANIFICACIÓN ANUAL DE ACTIVIDADES SYSO 2026 — Esta es la tabla maestra: planifico aquí todo el año
A2: ✏️ Cómo usar: 1) Escribí el nro. de semana (1-52). 2) Escribí la empresa (podés agregar nuevas). 3) Completá la actividad. El mes y la fecha se calculan solos. La Vista Semanal se actualiza automáticamente.
A3: SEMANA | B3: MES | C3: EMPRESA | D3: ACTIVIDAD | E3: FECHA PROGRAMADA | F3: FECHA REALIZADA | G3: ESTADO | H3: OBSERVACIONES
A4: =WEEKNUM(E4,2) -> 5 | B4: =TEXT(E4,"mmmm") -> Enero | C4: APLOMO | D4: Inspección de seguridad – Obra Bellevue | E4: =F4 -> 46050 | F4: 46050 | G4: HECHO
A5: =WEEKNUM(E5,2) -> 8 | B5: =TEXT(E5,"mmmm") -> Febrero | C5: APLOMO | D5: Inducción de Seguridad – Rubén Moreno | E5: =F5 -> 46072 | F5: 46072 | G5: HECHO
A6: =WEEKNUM(E6,2) -> 9 | B6: =TEXT(E6,"mmmm") -> Febrero | C6: APLOMO | D6: Inspección de seguridad – Obra Bellevue | E6: =F6 -> 46078 | F6: 46078 | G6: HECHO
A7: =WEEKNUM(E7,2) -> 10 | B7: =TEXT(E7,"mmmm") -> Marzo | C7: APLOMO | D7: Envío de índices de accidentabilidad enero y febrero 2026 | E7: =F7 -> 46087 | F7: 46087 | G7: HECHO
A8: =WEEKNUM(E8,2) -> 12 | B8: =TEXT(E8,"mmmm") -> Marzo | C8: APLOMO | D8: Inspección de seguridad | E8: =F8 -> 46100 | F8: 46100 | G8: HECHO
A9: =WEEKNUM(E9,2) -> 14 | B9: =TEXT(E9,"mmmm") -> Abril | C9: APLOMO | D9: Inspección de seguridad | E9: 46114 | G9: PROGRAMADO
A10: =WEEKNUM(E10,2) -> 16 | B10: =TEXT(E10,"mmmm") -> Abril | C10: APLOMO | D10: Inspección de seguridad | E10: 46128 | G10: PROGRAMADO
A11: =WEEKNUM(E11,2) -> 18 | B11: =TEXT(E11,"mmmm") -> Abril | C11: APLOMO | D11: Inspección de seguridad | E11: 46142 | G11: PROGRAMADO
A12: =WEEKNUM(E12,2) -> 22 | B12: =TEXT(E12,"mmmm") -> Mayo | C12: APLOMO | D12: Inspección de seguridad | E12: 46172 | G12: PROGRAMADO
A13: =WEEKNUM(E13,2) -> 27 | B13: =TEXT(E13,"mmmm") -> Junio | C13: APLOMO | D13: Inspección de seguridad | E13: 46202 | G13: PROGRAMADO
A14: =WEEKNUM(E14,2) -> 31 | B14: =TEXT(E14,"mmmm") -> Julio | C14: APLOMO | D14: Inspección de seguridad | E14: 46232 | G14: PROGRAMADO
A15: =WEEKNUM(E15,2) -> 35 | B15: =TEXT(E15,"mmmm") -> Agosto | C15: APLOMO | D15: Inspección de seguridad | E15: 46262 | G15: PROGRAMADO
A16: =WEEKNUM(E16,2) -> 39 | B16: =TEXT(E16,"mmmm") -> Setiembre | C16: APLOMO | D16: Inspección de seguridad | E16: 46292 | G16: PROGRAMADO
A17: =WEEKNUM(E17,2) -> 44 | B17: =TEXT(E17,"mmmm") -> Octubre | C17: APLOMO | D17: Inspección de seguridad | E17: 46322 | G17: PROGRAMADO
A18: =WEEKNUM(E18,2) -> 48 | B18: =TEXT(E18,"mmmm") -> Noviembre | C18: APLOMO | D18: Inspección de seguridad | E18: 46352 | G18: PROGRAMADO
A19: =WEEKNUM(E19,2) -> 50 | B19: =TEXT(E19,"mmmm") -> Diciembre | C19: APLOMO | D19: Inspección de seguridad | E19: 46367 | G19: PROGRAMADO
A20: =WEEKNUM(E20,2) -> 3 | B20: =TEXT(E20,"mmmm") -> Enero | C20: APLOMO | D20: Reporte mensual SYSO SACEEM | E20: 46038 | G20: PROGRAMADO
... A31: =WEEKNUM(E31,2) -> 49 | B31: =TEXT(E31,"mmmm") -> Diciembre | C31: APLOMO | D31: Reporte mensual SYSO SACEEM | E31: 46359 | G31: PROGRAMADO
A32: =WEEKNUM(E32,2) -> 4 | B32: =TEXT(E32,"mmmm") -> Enero | C32: ESON | D32: Avita Gard | E32: =F32 -> 46045 | F32: 46045 | G32: HECHO
A33: =WEEKNUM(E33,2) -> 5 | B33: =TEXT(E33,"mmmm") -> Enero | C33: ESON | D33: Inspección de seguridad – Obra Carrasco Hub | E33: =F33 -> 46050 | F33: 46050 | G33: HECHO
A34: =WEEKNUM(E34,2) -> 5 | B34: =TEXT(E34,"mmmm") -> Enero | C34: ESON | D34: Asamblea de seguridad | E34: =F34 -> 46052 | F34: 46052 | G34: HECHO
A35: =WEEKNUM(E35,2) -> 9 | B35: =TEXT(E35,"mmmm") -> Febrero | C35: ESON | D35: Inspección de seguridad – San Roque Montevideo Shopping | E35: =F35 -> 46078 | F35: 46078 | G35: HECHO
A36: =WEEKNUM(E36,2) -> 9 | B36: =TEXT(E36,"mmmm") -> Febrero | C36: ESON | D36: Asamblea de Seguridad – SUNCA | E36: =F36 -> 46079 | F36: 46079 | G36: HECHO
A37: =WEEKNUM(E37,2) -> 10 | B37: =TEXT(E37,"mmmm") -> Marzo | C37: ESON | D37: Inspección de seguridad – Obra Rubicón | E37: 46084 | F37: 46084 | G37: HECHO
A38: =WEEKNUM(E38,2) -> 11 | B38: =TEXT(E38,"mmmm") -> Marzo | C38: ESON | D38: Inspección de seguridad – Obra Avita Gard | E38: =F38 -> 46093 | F38: 46093 | G38: HECHO
A39: =WEEKNUM(E39,2) -> 12 | B39: =TEXT(E39,"mmmm") -> Marzo | C39: ESON | D39: Asamblea de seguridad SUNCA | E39: =F39 -> 46101 | F39: 46101 | G39: HECHO
A40: =WEEKNUM(E40,2) -> 13 | B40: =TEXT(E40,"mmmm") -> Marzo | C40: ESON | D40: Inspección de Seguridad | E40: 46106 | G40: PROGRAMADO
A41: =WEEKNUM(E41,2) -> 14 | B41: =TEXT(E41,"mmmm") -> Abril | C41: ESON | D41: Inspección de Seguridad | E41: =E40+7 -> 46113 | G41: PROGRAMADO
A42: =WEEKNUM(E42,2) -> 15 | B42: =TEXT(E42,"mmmm") -> Abril | C42: ESON | D42: Inspección de Seguridad | E42: =E41+7 -> 46120 | G42: PROGRAMADO
A43: =WEEKNUM(E43,2) -> 16 | B43: =TEXT(E43,"mmmm") -> Abril | C43: ESON | D43: Inspección de Seguridad | E43: =E42+7 -> 46127 | G43: PROGRAMADO
A44: =WEEKNUM(E44,2) -> 17 | B44: =TEXT(E44,"mmmm") -> Abril | C44: ESON | D44: Inspección de Seguridad | E44: =E43+7 -> 46134 | G44: PROGRAMADO
A45: =WEEKNUM(E45,2) -> 18 | B45: =TEXT(E45,"mmmm") -> Abril | C45: ESON | D45: Inspección de Seguridad | E45: =E44+7 -> 46141 | G45: PROGRAMADO
A46: =WEEKNUM(E46,2) -> 19 | B46: =TEXT(E46,"mmmm") -> Mayo | C46: ESON | D46: Inspección de Seguridad | E46: =E45+7 -> 46148 | G46: PROGRAMADO
A47: =WEEKNUM(E47,2) -> 20 | B47: =TEXT(E47,"mmmm") -> Mayo | C47: ESON | D47: Inspección de Seguridad | E47: =E46+7 -> 46155 | G47: PROGRAMADO
A48: =WEEKNUM(E48,2) -> 21 | B48: =TEXT(E48,"mmmm") -> Mayo | C48: ESON | D48: Inspección de Seguridad | E48: =E47+7 -> 46162 | G48: PROGRAMADO
A49: =WEEKNUM(E49,2) -> 22 | B49: =TEXT(E49,"mmmm") -> Mayo | C49: ESON | D49: Inspección de Seguridad | E49: =E48+7 -> 46169 | G49: PROGRAMADO
A50: =WEEKNUM(E50,2) -> 23 | B50: =TEXT(E50,"mmmm") -> Junio | C50: ESON | D50: Inspección de Seguridad | E50: =E49+7 -> 46176 | G50: PROGRAMADO
...

Sheet Vista Mensual
A1: ACTIVIDADES MENSUALES DE SYSO POR EMPRESA
A2: EMPRESA | E2: Escribir una fecha y se convierte en mes automatico (si se pone le mes la formula no funciona)
A3: TODAS | E3: 46093
A4: Item | B4: EMPRESA | C4: ACTIVIDAD | D4: FECHA | E4: ESTADO | F4: OBSERVACIONES
A5: 1 | B5: {=_xlfn._xlws.FILTER(CHOOSE({1,2,3,4,5},'Planificación Anual'!C4:C325,'Planificación Anual'!D4:D325,'Planificación Anual'!E4:E325,'Planificación Anual'!G4:G325,'Planificación Anual'!H4:H325),('Planificación Anual'!E4:E325<>"")*(TEXT('Planificación Anual'!E4:E325,"yyyymm")=TEXT('Vista Mensual'!E3,"yyyymm"))*IF('Vista Mensual'!A3="Todas",1,'Planificación Anual'!C4:C325='Vista Mensual'!A3),"sin respuesta")} -> APLOMO | C5: Envío de índices de accidentabilidad enero y febrero 2026 | D5: 46087 | E5: HECHO | F5: 0
A6: 2 | B6: APLOMO | C6: Inspección de seguridad | D6: 46100 | E6: HECHO | F6: 0
A7: 3 | B7: APLOMO | C7: Reporte mensual SYSO SACEEM | D7: 46084 | E7: PROGRAMADO | F7: 0
A8: 4 | B8: ESON | C8: Inspección de seguridad – Obra Rubicón | D8: 46084 | E8: HECHO | F8: 0
A9: 5 | B9: ESON | C9: Inspección de seguridad – Obra Avita Gard | D9: 46093 | E9: HECHO | F9: 0
A10: 6 | B10: ESON | C10: Asamblea de seguridad SUNCA | D10: 46101 | E10: HECHO | F10: 0
A11: 7 | B11: ESON | C11: Inspección de Seguridad | D11: 46106 | E11: PROGRAMADO | F11: 0
A12: 8 | B12: ESON | C12: Asamblea de seguridad SUNCA | D12: 46101 | E12: HECHO | F12: Acta enviada 30/03/2026
A13: 9 | B13: MOVIL UNO | C13: Capacitación Riesgo Químico y Simulacro de derrame de PQ | D13: 46105 | E13: HECHO | F13: Informe de Simulacro enviado 30/03/2026
A14: 10 | B14: MOVIL UNO | C14: Envié Informe de Inspecciones de Seguridad de Marzo | D14: 46111 | E14: HECHO | F14: 0
A15: 11 | B15: MOVIL UNO | C15: Inspección de Seguridad | D15: 46105 | E15: HECHO | F15: Informe de Simulacro enviado 30/03/2026
A16: 12 | B16: MOVIL UNO | C16: Reporte mensual de SST (requisito SGI) | D16: 46088 | E16: PROGRAMADO | F16: 0
A17: 13 | B17: OCEANUS | C17: Inspección de seguridad | D17: 46083 | E17: HECHO | F17: 0
A18: 14 | B18: OCEANUS | C18: Confección de informes – últimas dos semanas | D18: 46084 | E18: HECHO | F18: 0
A19: 15 | B19: OCEANUS | C19: Envío de informe semanal | D19: 46087 | E19: HECHO | F19: 0
A20: 16 | B20: OCEANUS | C20: Inspección de seguridad | D20: 46090 | E20: HECHO | F20: 0
A21: 17 | B21: OCEANUS | C21: Inspección de seguridad | D21: 46099 | E21: HECHO | F21: 0
A22: 18 | B22: OCEANUS | C22: Envío de reporte N.º 007 | D22: 46100 | E22: HECHO | F22: 0
A23: 19 | B23: OCEANUS | C23: Inspección de seguridad | D23: 46111 | E23: PROGRAMADO | F23: 0
A24: 20 | B24: RABUFFER | C24: Comunicación con Enrique para certificación | D24: 46084 | E24: HECHO | F24: 0
A25: 21 | B25: RABUFFER | C25: Inducción de Seguridad | D25: 46106 | E25: PROGRAMADO | F25: 0
A26: 22
A27: 23
A28: 24
A29: 25
A30: 26
A31: 27
A32: 28
A33: 29
A34: 30
A35: 31
A36: 32
A37: 33
... A115: 34
B116: ★ Para agregar una actividad hacerlo desde la hoja "Planificación Anual"

Sheet Vista Semanal
A1: VISTA SEMANAL
A2: EMPRESA | C2: SEMANA EscribirEl número de semana (del 1 al 52) | E2: 16
A3: TODAS
A4: =TEXT(DATE(2026,1,5)+(E2-1)*7,"MMMM YYYY") -> Abril 2026 | B4: =TEXT(DATE(2026,1,-2)+(E2-1)*7,"DD/MM") & " al " & TEXT(DATE(2026,1,-2)+(E2-1)*7+6,"DD/MM/YYYY") -> 13/04 al 19/04/2026 | D4: =COUNTIF('Planificación Anual'!$A$4:$A$325,E2)&" actividades programadas esta semana" -> 5 actividades programadas esta semana
A5: EMPRESA | B5: ACTIVIDAD | C5: FECHA | D5: ESTADO | E5: OBSERVACIONES
A6: {=_xlfn.LET(_xlpm.datos, 'Planificación Anual'!A4:H325, _xlpm.filtro, _xlfn._xlws.FILTER(_xlpm.datos, IFERROR(--'Planificación Anual'!A4:A325, 0) = --'Vista Semanal'!E2, "Sin actividades"), _xlfn.CHOOSECOLS(_xlpm.filtro, 3, 4, 5, 7, 8))} -> APLOMO | B6: Inspección de seguridad | C6: 46128 | D6: PROGRAMADO | E6: 0
A7: ESON | B7: Inspección de Seguridad | C7: 46127 | D7: PROGRAMADO | E7: 0
A8: ESON | B8: Bipartita | C8: 46127 | D8: PROGRAMADO | E8: 0
A9: OCEANUS | B9: Inspección de seguridad | C9: 46125 | D9: PROGRAMADO | E9: 0
A10: RABUFFER | B10: Capacitación manipulación manual de cargas | C10: 46126 | D10: PROGRAMADO | E10: 0
C189: =IFERROR(INDEX('Planificación Anual'!F$10:F$350, _xlfn.AGGREGATE(15, 6, (ROW('Planificación Anual'!$A$10:$A$350)-ROW('Planificación Anual'!$A$10)+1)/('Planificación Anual'!$A$10:$A$350=#REF!), ROWS($A$6:C189))), "") | D189: =IFERROR(INDEX('Planificación Anual'!G$10:G$350, _xlfn.AGGREGATE(15, 6, (ROW('Planificación Anual'!$A$10:$A$350)-ROW('Planificación Anual'!$A$10)+1)/('Planificación Anual'!$A$10:$A$350=#REF!), ROWS($A$6:D189))), "") | E189: =IFERROR(INDEX('Planificación Anual'!H$10:H$350, _xlfn.AGGREGATE(15, 6, (ROW('Planificación Anual'!$A$10:$A$350)-ROW('Planificación Anual'!$A$10)+1)/('Planificación Anual'!$A$10:$A$350=#REF!), ROWS($A$6:E189))), "")
C190: =IFERROR(INDEX('Planificación Anual'!F$10:F$350, _xlfn.AGGREGATE(15, 6, (ROW('Planificación Anual'!$A$10:$A$350)-ROW('Planificación Anual'!$A$10)+1)/('Planificación Anual'!$A$10:$A$350=#REF!), ROWS($A$6:C190))), "") | D190: =IFERROR(INDEX('Planificación Anual'!G$10:G$350, _xlfn.AGGREGATE(15, 6, (ROW('Planificación Anual'!$A$10:$A$350)-ROW('Planificación Anual'!$A$10)+1)/('Planificación Anual'!$A$10:$A$350=#REF!), ROWS($A$6:D190))), "") | E190: =IFERROR(INDEX('Planificación Anual'!H$10:H$350, _xlfn.AGGREGATE(15, 6, (ROW('Planificación Anual'!$A$10:$A$350)-ROW('Planificación Anual'!$A$10)+1)/('Planificación Anual'!$A$10:$A$350=#REF!), ROWS($A$6:E190))), "")
C191: =IFERROR(INDEX('Planificación Anual'!F$10:F$350, _xlfn.AGGREGATE(15, 6, (ROW('Planificación Anual'!$A$10:$A$350)-ROW('Planificación Anual'!$A$10)+1)/('Planificación Anual'!$A$10:$A$350=#REF!), ROWS($A$6:C191))), "") | D191: =IFERROR(INDEX('Planificación Anual'!G$10:G$350, _xlfn.AGGREGATE(15, 6, (ROW('Planificación Anual'!$A$10:$A$350)-ROW('Planificación Anual'!$A$10)+1)/('Planificación Anual'!$A$10:$A$350=#REF!), ROWS($A$6:D191))), "") | E191: =IFERROR(INDEX('Planificación Anual'!H$10:H$350, _xlfn.AGGREGATE(15, 6, (ROW('Planificación Anual'!$A$10:$A$350)-ROW('Planificación Anual'!$A$10)+1)/('Planificación Anual'!$A$10:$A$350=#REF!), ROWS($A$6:E191))), "")
C192: =IFERROR(INDEX('Planificación Anual'!F$10:F$350, _xlfn.AGGREGATE(15, 6, (ROW('Planificación Anual'!$A$10:$A$350)-ROW('Planificación Anual'!$A$10)+1)/('Planificación Anual'!$A$10:$A$350=#REF!), ROWS($A$6:C192))), "") | D192: =IFERROR(INDEX('Planificación Anual'!G$10:G$350, _xlfn.AGGREGATE(15, 6, (ROW('Planificación Anual'!$A$10:$A$350)-ROW('Planificación Anual'!$A$10)+1)/('Planificación Anual'!$A$10:$A$350=#REF!), ROWS($A$6:D192))), "") | E192: =IFERROR(INDEX('Planificación Anual'!H$10:H$350, _xlfn.AGGREGATE(15, 6, (ROW('Planificación Anual'!$A$10:$A$350)-ROW('Planificación Anual'!$A$10)+1)/('Planificación Anual'!$A$10:$A$350=#REF!), ROWS($A$6:E192))), "")
C193: =IFERROR(INDEX('Planificación Anual'!F$10:F$350, _xlfn.AGGREGATE(15, 6, (ROW('Planificación Anual'!$A$10:$A$350)-ROW('Planificación Anual'!$A$10)+1)/('Planificación Anual'!$A$10:$A$350=#REF!), ROWS($A$6:C193))), "") | D193: =IFERROR(INDEX('Planificación Anual'!G$10:G$350, _xlfn.AGGREGATE(15, 6, (ROW('Planificación Anual'!$A$10:$A$350)-ROW('Planificación Anual'!$A$10)+1)/('Planificación Anual'!$A$10:$A$350=#REF!), ROWS($A$6:D193))), "") | E193: =IFERROR(INDEX('Planificación Anual'!H$10:H$350, _xlfn.AGGREGATE(15, 6, (ROW('Planificación Anual'!$A$10:$A$350)-ROW('Planificación Anual'!$A$10)+1)/('Planificación Anual'!$A$10:$A$350=#REF!), ROWS($A$6:E193))), "")
A274: ★ Actividades los días MARTES 07:00-08:00 hs | Para agregar usá la hoja "Planificación Anual"

Sheet Accidentes
A1: SEGUMIENTO GENERAL DE ACCIDENTES
A3: Item | B3: Año | C3: Fecha | D3: Empresa | E3: Accidentado | F3: Descripción del Accidete | G3: N° de Denuncia BSE | H3: Fecha Alta BSE | I3: Total días perdidas | J3: Investigación
A4: 1 | D4: ESON | E4: Enrique Soria | F4: Rotura de puerta de vidrio | J4: NO
A5: 2 | C5: 46064 | D5: MOVIL UNO | E5: Guzmán Martinez | F5: Quemadura de cuello, hombro y nuca izquierdos; con fluido refrigerante de grúa | J5: SI
A6: 3
A7: 4
A8: 5
A9: 6
A10: 7
A11: 8
A12: 9
A13: 10
A14: 11
A15: 12
A16: 13
A17: 14
A18: 15

Sheet Listas
A1: TIPO | C1: ESTADO | E1: EMPRESAS | G1: Meses
A2: Capacitación | C2: PROGRAMADO | E2: TODAS | G2: Enero | I2: {=_xludf.UNIQUE('Planificación Anual'!C4:C325)} -> #NAME?
A3: Inspección | C3: HECHO | E3: MOVIL UNO | G3: Febrero
A4: Simulacro | C4: VENCIDA | E4: RABUFFER | G4: Marzo
A5: Bipartita | C5: CANCELADO | E5: APLOMO | G5: Abril
A6: Informe | C6: PENDIENTE | E6: FEWELL | G6: Mayo
A7: Asamblea | E7: OCEANUS | G7: Junio
G8: Julio
G9: Agosto
G10: Setiembre
G11: Octubre
G12: Noviembre
G13: Diciembre
A15: Crear la lista de opciones para la lista desplegable en otra hoja
A16: Ahora vas a la columna donde quiero que este la lista desplegable
A17: 1. Seleccioná las celdas donde querés la lista
A18: (por ejemplo D3:D300).
A19: 2. Ir a:
A20: Datos
A21: → Validación de datos
A22: 3. En Permitir elegí:
A23: Lista
A24: 4. En Origen escribí:
A25: Selecciono en la hoja lista lo que quiero que tenga (la lista que generé)
A26: 5. Aceptar.

Sheet _Lookup
A1: Semana | B1: MOVIL UNO_act1 | C1: MOVIL UNO_act2 | D1: MOVIL UNO_act3 | E1: RABUFFER_act1 | F1: RABUFFER_act2 | G1: RABUFFER_act3 | H1: ESON_act1 | I1: ESON_act2 | J1: ESON_act3 | K1: FEWELL_act1 | L1: FEWELL_act2 | M1: FEWELL_act3 | N1: APLOMO_act1 | O1: APLOMO_act2 | P1: APLOMO_act3
A2: 1
A3: 2 | N3: Presentación del Plan de Seguridad
A4: 3 | B4: Capacitación Funciones Delegado de Seguridad (Solo con Sergio CANESSI)
A5: 4 | B5: Capacitación orden y limpieza
A6: 5 | K6: Inducción de Seguridad
A7: 6 | B7: Simulacro de incendio
A8: 7 | N8: Capacitación trabajos en altura
A9: 8 | H9: Capacitación manipulación manual de cargas
A10: 9
A11: 10 | B11: Capacitación trabajos en espacios confinados | K11: Capacitación orden y limpieza
A12: 11
A13: 12 | N13: Capacitación EPP y uso correcto
A14: 13 | B14: Reunión Bipartita | C14: Inspección de Seguridad en taller | D14: Reporte mensual de SST (requisito SGI) | K14: Reporte mensual SYSO | N14: Reporte mensual SYSO
A15: 14 | E15: Inducción de Seguridad | K15: Reunión Bipartita
A16: 15 | H16: Bipartita
A17: 16 | H17: Capacitación orden y limpieza
A18: 17 | B18: Reporte mensual de SST (requisito SGI) | E18: Capacitación manipulación manual de cargas | K18: Reporte mensual SYSO | N18: Reporte mensual SYSO
A19: 18 | B19: Simulacro de actuación ante accidente | C19: Inspección de Seguridad en taller | N19: Reunión Bipartita
A20: 19 | K20: Capacitación riesgo eléctrico
A21: 20 | H21: Capacitación Riesgo eléctrico
A22: 21 | E22: Reunión Bipartita | K22: Reporte mensual SYSO | N22: Reporte mensual SYSO
A23: 22 | B23: Capacitación riesgos químicos
A24: 23 | B24: Inspección de Seguridad en taller
A25: 24 | H25: Capacitación contaminantes químicos | N25: Simulacro de incendio
A26: 25 | B26: Reporte mensual de SST (requisito SGI) | H26: Bipartita | K26: Reporte mensual SYSO | N26: Reporte mensual SYSO
A27: 26
A28: 27 | B28: Inspección de Seguridad en taller | K28: Reunión Bipartita
A29: 28 | K29: Simulacro de evacuación
A30: 29 | B30: Reporte mensual de SST (requisito SGI) | K30: Reporte mensual SYSO | N30: Reporte mensual SYSO
A31: 30 | E31: Capacitación y simulacro de actuación ante Emergencias | N31: Capacitación riesgos químicos
A32: 31 | B32: Inspección de Seguridad en taller
A33: 32 | H33: Capacitación actuación ante emergencias
A34: 33 | B34: Reporte mensual de SST (requisito SGI) | K34: Reporte mensual SYSO | N34: Reporte mensual SYSO
A35: 34 | N35: Reunión Bipartita
A36: 35 | K36: Inspección de Seguridad
A37: 36 | B37: Inspección de Seguridad en taller | H37: Capacitación uso herramientas eléctricas
A38: 37 | B38: Reporte mensual de SST (requisito SGI) | E38: Inspección de Seguridad en depósito y oficinas | K38: Reporte mensual SYSO | N38: Reporte mensual SYSO
A39: 38 | N39: Inspección de Seguridad general
A40: 39 | H40: Bipartita
...
